============================= test session starts ==============================
2: platform darwin -- Python 3.6.5, pytest-4.2.0, py-1.5.3, pluggy-0.8.1 -- /Users/YupengTANG/anaconda3/bin/python
2: cachedir: .pytest_cache
2: rootdir: /Users/YupengTANG/Documents/GitHub/jiffy-test-fix/jiffy/build/pyjiffy, inifile: setup.cfg
2: plugins: cov-2.6.1, remotedata-0.2.1, openfiles-0.3.0, doctestplus-0.1.3, arraydiff-0.2
2: collecting ... collected 8 items
2: 
2: test/test_client.py::TestClient::test_chain_replication ERROR            [ 12%]
2: test/test_client.py::TestClient::test_close ERROR                        [ 25%]
2: test/test_client.py::TestClient::test_create ERROR                       [ 37%]
2: test/test_client.py::TestClient::test_failures ERROR                     [ 50%]
2: test/test_client.py::TestClient::test_lease_worker ERROR                 [ 62%]
2: test/test_client.py::TestClient::test_notifications ERROR                [ 75%]
2: test/test_client.py::TestClient::test_open ERROR                         [ 87%]
2: test/test_client.py::TestClient::test_sync_remove ERROR                  [100%]
2: 
2: ==================================== ERRORS ====================================
2: _____________ ERROR at setup of TestClient.test_chain_replication ______________
2: 
2: item = <TestCaseFunction test_chain_replication>
2: 
2:     def pytest_runtest_setup(item):
2:     
2: >       remote_data = item.get_marker('remote_data')
2: E       AttributeError: 'TestCaseFunction' object has no attribute 'get_marker'
2: 
2: /Users/YupengTANG/anaconda3/lib/python3.6/site-packages/pytest_remotedata/plugin.py:59: AttributeError
2: ___________________ ERROR at setup of TestClient.test_close ____________________
2: 
2: item = <TestCaseFunction test_close>
2: 
2:     def pytest_runtest_setup(item):
2:     
2: >       remote_data = item.get_marker('remote_data')
2: E       AttributeError: 'TestCaseFunction' object has no attribute 'get_marker'
2: 
2: /Users/YupengTANG/anaconda3/lib/python3.6/site-packages/pytest_remotedata/plugin.py:59: AttributeError
2: ___________________ ERROR at setup of TestClient.test_create ___________________
2: 
2: item = <TestCaseFunction test_create>
2: 
2:     def pytest_runtest_setup(item):
2:     
2: >       remote_data = item.get_marker('remote_data')
2: E       AttributeError: 'TestCaseFunction' object has no attribute 'get_marker'
2: 
2: /Users/YupengTANG/anaconda3/lib/python3.6/site-packages/pytest_remotedata/plugin.py:59: AttributeError
2: __________________ ERROR at setup of TestClient.test_failures __________________
2: 
2: item = <TestCaseFunction test_failures>
2: 
2:     def pytest_runtest_setup(item):
2:     
2: >       remote_data = item.get_marker('remote_data')
2: E       AttributeError: 'TestCaseFunction' object has no attribute 'get_marker'
2: 
2: /Users/YupengTANG/anaconda3/lib/python3.6/site-packages/pytest_remotedata/plugin.py:59: AttributeError
2: ________________ ERROR at setup of TestClient.test_lease_worker ________________
2: 
2: item = <TestCaseFunction test_lease_worker>
2: 
2:     def pytest_runtest_setup(item):
2:     
2: >       remote_data = item.get_marker('remote_data')
2: E       AttributeError: 'TestCaseFunction' object has no attribute 'get_marker'
2: 
2: /Users/YupengTANG/anaconda3/lib/python3.6/site-packages/pytest_remotedata/plugin.py:59: AttributeError
2: _______________ ERROR at setup of TestClient.test_notifications ________________
2: 
2: item = <TestCaseFunction test_notifications>
2: 
2:     def pytest_runtest_setup(item):
2:     
2: >       remote_data = item.get_marker('remote_data')
2: E       AttributeError: 'TestCaseFunction' object has no attribute 'get_marker'
2: 
2: /Users/YupengTANG/anaconda3/lib/python3.6/site-packages/pytest_remotedata/plugin.py:59: AttributeError
2: ____________________ ERROR at setup of TestClient.test_open ____________________
2: 
2: item = <TestCaseFunction test_open>
2: 
2:     def pytest_runtest_setup(item):
2:     
2: >       remote_data = item.get_marker('remote_data')
2: E       AttributeError: 'TestCaseFunction' object has no attribute 'get_marker'
2: 
2: /Users/YupengTANG/anaconda3/lib/python3.6/site-packages/pytest_remotedata/plugin.py:59: AttributeError
2: ________________ ERROR at setup of TestClient.test_sync_remove _________________
2: 
2: item = <TestCaseFunction test_sync_remove>
2: 
2:     def pytest_runtest_setup(item):
2:     
2: >       remote_data = item.get_marker('remote_data')
2: E       AttributeError: 'TestCaseFunction' object has no attribute 'get_marker'
2: 
2: /Users/YupengTANG/anaconda3/lib/python3.6/site-packages/pytest_remotedata/plugin.py:59: AttributeError
2: =========================== 8 error in 0.23 seconds ============================
2/3 Test #2: PythonClientTest .................***Failed    5.39 sec
